<?xml version="1.0"?>
<robot
  name="Gripper2">
  <link
    name="base_link">
    <inertial>
      <origin
        xyz="-0.00018381429775776 -1.12295880039248E-07 0.0491407595300528"
        rpy="0 0 0" />
      <mass
        value="0.670577926069558" />
      <inertia
        ixx="0.000364869467999578"
        ixy="-3.06546854671999E-08"
        ixz="2.0254723799717E-06"
        iyy="0.00036486341299996"
        iyz="-1.06002278351788E-07"
        izz="2.18826103188424E-05" />
    </inertial>
    <visual>
      <origin
        xyz="0 0 0"
        rpy="0 0 0" />
      <geometry>
        <mesh
          filename="package://Gripper2/meshes/base_link.STL" />
      </geometry>
      <material
        name="">
        <color
          rgba="0.792156862745098 0.819607843137255 0.933333333333333 1" />
      </material>
    </visual>
    <collision>
      <origin
        xyz="0 0 0"
        rpy="0 0 0" />
      <geometry>
        <mesh
          filename="package://Gripper2/meshes/base_link.STL" />
      </geometry>
    </collision>
  </link>
  <link
    name="Mors_prismatic1_Link">
    <inertial>
      <origin
        xyz="0.00925 0.0095206 0.0097917"
        rpy="0 0 0" />
      <mass
        value="0.05231" />
      <inertia
        ixx="1.8004E-05"
        ixy="6.4269E-20"
        ixz="-3.3881E-21"
        iyy="8.7579E-08"
        iyz="8.9191E-07"
        izz="1.7917E-05" />
    </inertial>
    <visual>
      <origin
        xyz="0 0 0"
        rpy="0 0 0" />
      <geometry>
        <mesh
          filename="package://Gripper2/meshes/Mors_prismatic1_Link.STL" />
      </geometry>
      <material
        name="">
        <color
          rgba="0.79216 0.81961 0.93333 1" />
      </material>
    </visual>
    <collision>
      <origin
        xyz="0 0 0"
        rpy="0 0 0" />
      <geometry>
        <mesh
          filename="package://Gripper2/meshes/Mors_prismatic1_Link.STL" />
      </geometry>
    </collision>
  </link>
  <joint
    name="Mors_prismatic1_joint"
    type="prismatic">
    <origin
      xyz="0.0014158 -0.020952 0.0995"
      rpy="1.5708 0 0.5236" />
    <parent
      link="base_link" />
    <child
      link="Mors_prismatic1_Link" />
    <axis
      xyz="0 0 1" />
    <limit
      lower="0"
      upper="1"
      effort="100"
      velocity="10" />
    <calibration
      rising="0"
      falling="0" />
    <dynamics
      damping="0"
      friction="0" />
    <safety_controller
      soft_upper="0"
      soft_lower="0"
      k_position="0"
      k_velocity="0" />
  </joint>
  <link
    name="Mors_prismatic2_Link">
    <inertial>
      <origin
        xyz="0.00925 0.0095206 0.0097917"
        rpy="0 0 0" />
      <mass
        value="0.05231" />
      <inertia
        ixx="1.8004E-05"
        ixy="6.9606E-20"
        ixz="-4.6684E-21"
        iyy="8.7579E-08"
        iyz="8.9191E-07"
        izz="1.7917E-05" />
    </inertial>
    <visual>
      <origin
        xyz="0 0 0"
        rpy="0 0 0" />
      <geometry>
        <mesh
          filename="package://Gripper2/meshes/Mors_prismatic2_Link.STL" />
      </geometry>
      <material
        name="">
        <color
          rgba="0.79216 0.81961 0.93333 1" />
      </material>
    </visual>
    <collision>
      <origin
        xyz="0 0 0"
        rpy="0 0 0" />
      <geometry>
        <mesh
          filename="package://Gripper2/meshes/Mors_prismatic2_Link.STL" />
      </geometry>
    </collision>
  </link>
  <joint
    name="Mors_prismatic2_joint"
    type="prismatic">
    <origin
      xyz="0.017437 0.011702 0.0995"
      rpy="1.5708 0 2.618" />
    <parent
      link="base_link" />
    <child
      link="Mors_prismatic2_Link" />
    <axis
      xyz="0 0 1" />
    <limit
      lower="0"
      upper="1"
      effort="100"
      velocity="10" />
  </joint>
  <link
    name="Mors_prismatic3_Link">
    <inertial>
      <origin
        xyz="0.00925 0.0095206 0.0097917"
        rpy="0 0 0" />
      <mass
        value="0.05231" />
      <inertia
        ixx="1.8004E-05"
        ixy="6.4586E-20"
        ixz="-4.2352E-21"
        iyy="8.7579E-08"
        iyz="8.9191E-07"
        izz="1.7917E-05" />
    </inertial>
    <visual>
      <origin
        xyz="0 0 0"
        rpy="0 0 0" />
      <geometry>
        <mesh
          filename="package://Gripper2/meshes/Mors_prismatic3_Link.STL" />
      </geometry>
      <material
        name="">
        <color
          rgba="0.79216 0.81961 0.93333 1" />
      </material>
    </visual>
    <collision>
      <origin
        xyz="0 0 0"
        rpy="0 0 0" />
      <geometry>
        <mesh
          filename="package://Gripper2/meshes/Mors_prismatic3_Link.STL" />
      </geometry>
    </collision>
  </link>
  <joint
    name="Mors_prismatic3_joint"
    type="prismatic">
    <origin
      xyz="-0.018853 0.00925 0.0995"
      rpy="1.5708 0 -1.5708" />
    <parent
      link="base_link" />
    <child
      link="Mors_prismatic3_Link" />
    <axis
      xyz="0 0 1" />
    <limit
      lower="0"
      upper="1"
      effort="100"
      velocity="10" />
    <calibration
      rising="0"
      falling="0" />
    <dynamics
      damping="0"
      friction="0" />
    <safety_controller
      soft_upper="0"
      soft_lower="0"
      k_position="0"
      k_velocity="0" />
  </joint>
</robot>
